Workbook
Name _YF62: #REF!
Name _YF62: #REF!
Name a: #REF!
Name a: #REF!
Name aa: #REF!
Name aa: #REF!
Name ai: #REF!
Name d: #REF!
Name fd: #REF!
Name UFPrn20041029131906: #REF!
Name UFPrn20041029131906: [1]调料!$A$1:$J$144
Name UFPrn20050216095615: #REF!
Name UFPrn20050307135853: #REF!
Name UFPrn20050307135853: [2]五金修理!$A$1:$H$28
Name UFPrn20050405115938: #REF!
Name UFPrn20050405115938: [3]五金修理!$A$1:$H$32
Name UFPrn20050531234857: #REF!
Name UFPrn20050604102429: #REF!
Name UFPrn20050604102429: [4]五金修理!$A$1:$H$38
Name UFPrn20051112111507: #REF!
Name UFPrn20051115100611: #REF!
Name UFPrn20051116113943: #REF!
Name UFPrn20051130140252: #REF!
Name UFPrn20051130140918: #REF!
Name UFPrn20051130153829: #REF!
Name UFPrn20051205152128: #REF!
Name UFPrn20051206142109: #REF!
Name UFPrn20051206142133: #REF!
Name UFPrn20051208163508: #REF!
Name UFPrn20051208163649: #REF!
Name UFPrn20051231133804: #REF!
Name UFPrn20051231133828: #REF!
Name UFPrn20051231133858: #REF!
Name UFPrn20051231134621: #REF!
Name UFPrn20060102184637: #REF!
Name UFPrn20060102184746: #REF!
Name UFPrn20060104215017: #REF!
Name UFPrn20060104221403: #REF!
Name UFPrn20060105154236: #REF!
Name UFPrn20060105154306: #REF!
Name UFPrn20060112094127: #REF!
Name X: #REF!
Name 啊啊: #REF!
Name 吧: #REF!
Name 橙子葡萄: #REF!
Name 地方: #REF!
Name 额: #REF!
Name 噶4: #REF!
Name 利乐标准: #REF!
Name 米果: #REF!
Name 其他: #REF!
Name 其他1: #REF!
Name 是: #REF!
Name 我: #REF!
Name 线别产值分析: #REF!
Name 新品: #REF!

Sheet 目标设置规则 v2
C2: 目标设置规则：组织+人（组织是看这个组织的所有层级的是否有人）
C3: 目标分类 | D3: 层级 | E3: 季度/月度目标 | F3: 制定人 | G3: 目标设置审核节点 | I3: 目标制定规则 | J3: 人员异动 目标设置规则 | N3: 目标设置路径
J4: 人员异动场景 | L4: 目标设置理规则 | M4: 提成计算
C5: 组织目标 | D5: 总部 | E5: 单位主管确认的组织总的季度目标，由销售运营部导入系统，组织月度目标由大区月度目标汇总 | F5: 单位主管 | G5: 无需审核 | H5: 大区目标导入后，需在系统提示的规定时间内完成下级季度目标设置，超过时间则不能设置 总部导入大区目标记为 D 日，各级时效可配置，默认每级 3 天； 大区→省区截止 D+n1；省区→分公司 D+n1+n2；分公司→营业所 D+n1+n2+n3； 超时未审核自动通过，超时未填报禁止填写。示例：4.1 导入，依次截止 4.4、4.7、4.10 23:59。 | I5: 1. 自上而下的逐级拆解规则： 目标拆解必须遵循「总部→大区→省区→分公司→营业所」的路径 2. 目标总额平衡规则： a、当前组织目标 = 下级在岗人员目标（已分配） + 空挂池目标（未分配） b、季度目标=月度目标之和 3. 空挂池目标管理规则 空挂池目标为 “未分配至在岗人员的目标”，用于平衡本级目标总额与已分配人员目标的差额 a、空挂池 目标不能高于管控目标 N万（管控目标=上级组织目标*空岗组织的人口占比） b、当前组织空岗，下属岗位有人，需要设置目标； c、当前组织空岗，下属岗位没有人，不需要设置目标（系统里是灰色的） d、当前组织未启动，不需要设置组织目标（系统里是灰色） 4. 新入职人员目标设置规则： 新入职人员5天内设置目标，从空挂池分配目标，未设置目标，则无提成 备注：1、如新入职人员当前所在的目标是0，则要返回上级去设置目标，上级目标设置审批后，才能给新人设置目标； 2、如新入职人员当前组织目标已分配完，空挂池目标是0，则不能分配目标 | J5: ① 季度内入职 | K5: a、岗位已有月 / 季目标 b、岗位无月 / 季目标 | L5: a、岗位已有目标的，按现有目标不调整 b、岗位无目标从空挂池分配目标 | M5: 个人考核目标按100% 计算达成 未设置目标则无提成
D6: 大区 | E6: 单位主管确认的季度目标，大区自行拆分月度目标 | F6: 单位主管 | G6: 无需审核 | J6: ② 季度内离职 | K6: 岗位按原目标 | L6: 岗位目标不调整 | M6: 个人考核目标按原目标计算达成 （岗位目标不折算）
D7: 省区 | E7: 1、由大区总监制定省区季度/月度目标 2、如某个省区组织人数是0，则不需要设置目标；如没有负责人，但下级有人（包含兼岗），需分配目标），剩余目标放入空挂池，空挂池目标不能超过空挂目标管控上限 | F7: 大区总监 | G7: 单位主管审核 | J7: ③ 季度内增加或取消兼岗 | K7: a-1、增加的兼岗已有月 / 季目标 a-2、增加的兼岗无月 / 季目标 b、取消兼岗，目标不取消 | L7: a-1、兼岗已有目标的，按现有目标不调整 a-2、兼岗无目标从空挂池分配目标 b、取消兼岗 ，目标不调整 | M7: 个人考核目标 分为 主岗目标 和兼岗目标，分开计算达成 （兼岗目标不折算）
D8: 分公司 | E8: 1、由省区总监制定公司季度/月度目标 2、如某个分公司组织人数是0，则不需要设置目标；如没有负责人，但下级有人（包含兼岗），需分配目标），剩余目标放入空挂池，空挂池目标不能超过空挂目标管控上限 | F8: 省区总监 | G8: 大区总监审核 | J8: ④季度内 主岗同岗位异动 | K8: a、异动岗位已有月 / 季目标 b、异动岗位无月 / 季目标 | L8: a、岗位已有目标的，按现有目标不调整 b、岗位无目标从空挂池分配目标目标 | M8: 个人考核目标分为异动前岗位目标和异动后岗位目标 分开计算达成 （异动前后岗位目标不折算）
D9: 营业所 | E9: 1、由区域总监制定营业所季度/月度目标 2、如某个营业所组织人数是0，则不需要设置目标；剩余目标放入空挂池，空挂池目标不能超过空挂目标管控上限 | F9: 区域总监 | G9: 省区总监审核 | J9: ⑤季度内 升职 / 降职异动 | K9: a、升职/降职 岗位已有月 / 季目标 b、升职/降职 岗位无月 / 季目标 | L9: a、岗位已有目标的，不调整 b、岗位无目标从空挂池分配 | M9: 个人考核目标分为异动前岗位目标和异动后岗位目标 分开计算达成 （异动前后岗位目标不折算）
C10: 合伙人目标 | D10: 合伙人 | E10: 有区域经理：区域经理根据当前营业所目标拆分合伙人目标 | F10: 区域经理 | G10: 由设置人上级审核 | H10: 1、正常每月15号前进行目标设置 2、新入职合伙人 入职5天内设置目标 3、合伙人目标设置需选到对应的营业所设置目标 | I10: 营业所合伙人季度目标总和 ≥ 当前营业所季度目标 | J10: 已设置的合伙人季度目标不能做调整
E11: 无区域经理：由上级进行拆分合伙人目标 | F11: 上级 | I11: 合伙人季度/月度目标≥最低管控季度/月度目标
E12: 新入职合伙人：入职5天内置季度/月度目标 | F12: 区域经理或上级 | I12: 新入职合伙人季度/月度目标≥最低管控季度/月度目标

Sheet 目标设置规则
C2: 目标设置规则：组织+人（组织是看这个组织的所有层级的是否有人）
C3: 目标分类 | D3: 层级 | E3: 季度/月度目标 | F3: 制定人 | G3: 目标设置审核节点 | I3: 目标制定规则 | J3: 人员异动 目标设置规则 | N3: 目标设置路径
J4: 人员异动场景 | L4: 目标设置理规则 | M4: 提成计算
C5: 组织目标 | D5: 总部 | E5: 单位主管确认的组织总的季度目标，由销售运营部导入系统，组织月度目标由大区月度目标汇总 | F5: 单位主管 | G5: 无需审核 | H5: 大区目标导入后，需在系统提示的规定时间内完成下级季度目标设置，超过时间则不能设置 总部导入大区目标记为 D 日，各级时效可配置，默认每级 3 天； 大区→省区截止 D+n1；省区→分公司 D+n1+n2；分公司→营业所 D+n1+n2+n3； 超时未审核自动通过，超时未填报禁止填写。示例：4.1 导入，依次截止 4.4、4.7、4.10 23:59。 | I5: 1. 自上而下的逐级拆解规则： 目标拆解必须遵循「总部→大区→省区→分公司→营业所」的路径 2. 目标总额平衡规则： a、当前组织目标 = 下级在岗人员目标（已分配） + 空挂池目标（未分配） b、季度目标=月度目标之和 3. 空挂池目标管理规则 空挂池目标为 “未分配至在岗人员的目标”，用于平衡本级目标总额与已分配人员目标的差额 a、空挂池 目标不能高于管控目标 N万（管控目标=上级组织目标*空岗组织的人口占比） b、当前组织空岗，下属岗位有人，需要设置目标； c、当前组织空岗，下属岗位没有人，不需要设置目标（系统里是灰色的） d、当前组织未启动，不需要设置组织目标（系统里是灰色） 4. 新入职人员目标设置规则： 新入职人员5天内设置目标，从空挂池分配目标，未设置目标，则无提成 备注：1、如新入职人员当前所在的目标是0，则要返回上级去设置目标，上级目标设置审批后，才能给新人设置目标； 2、如新入职人员当前组织目标已分配完，空挂池目标是0，则不能分配目标 | J5: ① 季度内入职 | K5: a、岗位已有月 / 季目标 b、岗位无月 / 季目标 | L5: a、岗位已有目标的，按现有目标不调整 b、岗位无目标从空挂池分配目标 | M5: 个人考核目标按100% 计算达成 未设置目标则无提成
D6: 大区 | E6: 单位主管确认的季度目标，大区自行拆分月度目标 | F6: 单位主管 | G6: 无需审核 | J6: ② 季度内离职 | K6: 岗位按原目标 | L6: 岗位目标不调整 | M6: 个人考核目标按原目标计算达成 （岗位目标不折算）
D7: 省区 | E7: 1、由大区总监制定省区季度/月度目标 2、如某个省区组织人数是0，则不需要设置目标；如没有负责人，但下级有人（包含兼岗），需分配目标），剩余目标放入空挂池，空挂池目标不能超过空挂目标管控上限 | F7: 大区总监 | G7: 单位主管审核 | J7: ③ 季度内增加或取消兼岗 | K7: a-1、增加的兼岗已有月 / 季目标 a-2、增加的兼岗无月 / 季目标 b、取消兼岗，目标不取消 | L7: a-1、兼岗已有目标的，按现有目标不调整 a-2、兼岗无目标从空挂池分配目标 b、取消兼岗 ，目标不调整 | M7: 个人考核目标 = 主岗目标 + 兼岗目标 计算达成 （兼岗目标不折算）
D8: 分公司 | E8: 1、由省区总监制定公司季度/月度目标 2、如某个分公司组织人数是0，则不需要设置目标；如没有负责人，但下级有人（包含兼岗），需分配目标），剩余目标放入空挂池，空挂池目标不能超过空挂目标管控上限 | F8: 省区总监 | G8: 大区总监审核 | J8: ④季度内 主岗同岗位异动 | K8: a、异动岗位已有月 / 季目标 b、异动岗位无月 / 季目标 | L8: a、岗位已有目标的，按现有目标不调整 b、岗位无目标从空挂池分配目标目标 | M8: 个人考核目标=异动前岗位目标+异动后岗位目标 （异动前后岗位目标不折算）
D9: 营业所 | E9: 1、由区域总监制定营业所季度/月度目标 2、如某个营业所组织人数是0，则不需要设置目标；剩余目标放入空挂池，空挂池目标不能超过空挂目标管控上限 | F9: 区域总监 | G9: 省区总监审核 | J9: ⑤季度内 升职 / 降职异动 | K9: a、升职/降职 岗位已有月 / 季目标 b、升职/降职 岗位无月 / 季目标 | L9: a、岗位已有目标的，不调整 b、岗位无目标从空挂池分配 | M9: 个人考核目标分段计算 （异动前后岗位目标不折算）
C10: 合伙人目标 | D10: 合伙人 | E10: 有区域经理：区域经理根据当前营业所目标拆分合伙人目标 | F10: 区域经理 | G10: 由设置人上级审核 | H10: 1、正常每月15号前进行目标设置 2、新入职合伙人 入职5天内设置目标 需选到对应的营业所设置目标 | I10: 营业所合伙人季度目标总和 ≥ 当前营业所季度目标 | J10: 已设置的合伙人季度目标不能做调整
E11: 无区域经理：由上级进行拆分合伙人目标 | F11: 上级 | I11: 合伙人季度/月度目标≥最低管控季度/月度目标
E12: 新入职合伙人：入职5天内置季度/月度目标 | F12: 区域经理或上级 | I12: 新入职合伙人季度/月度目标≥最低管控季度/月度目标

Sheet 目标达成率考核
B2: 月度、季度目标达成率考核 考核对象：全国销售总监 & 大区总监 产品组：全组别 考核项目：月度、季度目标达成率 考核周期：月度、自然季度 考核内容： 1、月度目标达成率 < 85%，申诫1次 2、季度目标达成率 < 75%，小过1次 说明： 目标达成率考核：主兼岗分开考核

Sheet 汰换特批规则-26.7
B2: 造旺销售组 汰换特批规则（考核标准）
B4: 考核组别 | H4: 考核岗位 | I4: 考核周期 | J4: 考核指标 | K4: 达标要求 | L4: 不达标处理 | M4: 汰换人员特批-审批流程 | R4: 生效/执行 时间 | S4: 备注
B5: 标箱组 | C5: 儿童乳品组 | D5: 大师兄-冲刺组 | E5: 糖果组 | F5: 旺旺乳品组 | G5: 酒品组 | M5: 区域总监 | N5: 省区总监 | O5: 大区总监 | P5: 全国销售总监 | Q5: 单位主管 （Leo）
B6: ✅ | C6: ✅ | D6: ✅ | E6: ✅ | F6: ✅ | G6: ✅ | H6: 大区总监 | I6: 单季度考核 （完整季度在岗） | J6: 季度目标达成率 | K6: 季度≥50% | L6: 1、不达标 汰换：季度 目标达成率<50% | M6: / | N6: / | O6: / | P6: ✅ | Q6: ✅ | R6: 45748 | S6: 1、考核数据为组内主兼岗汇总数据 2、跨组兼岗的考核主岗所在组数据 3、季度末最后一个月考核： （考核岗位包含 省区总监，区域总监，区域经理） 1）非完整季度在岗 ，按月度考核 2）完整季度在岗，按季度考核 3）季度内 主岗 异动，属于非完整季度在岗，按月度考核 （季度考核：a、季度达标，最后一个月未达标，不进入汰换区；b、季度未达标，最后一个月达标，进入汰换区） 4、儿童乳品组26年4月1日取消月度考核 5、汰换特批 每月截止时间：15号
L7: 2、末位淘汰 汰换：季度 目标达成率排名为同产品组排名最后一名且<100% （假如此季度组内已有大区总监汰换那就不生效）
I8: 双季度考核 （完整季度在岗） | J8: 连续两个季度目标达成率 | K8: 连续两个季度≥75% | L8: 3、不达标 汰换：连续两个季度 目标达成率<75% | R8: 2026/1/1 （26年Q2执行）
B10: ✅ | C10: / | D10: ✅ | E10: ✅ | F10: ✅ | G10: ✅ | H10: 省区总监 | I10: 月度考核 （完整月度在岗） | J10: 月度目标达成率 | K10: 月度≥50% | L10: 1、不达标 汰换：月度 目标达成率<50% | M10: / | N10: / | O10: ✅ | P10: / | Q10: / | R10: 2026/1/1 （26年1月执行）
I11: 单季度考核 （完整季度在岗） | J11: 季度目标达成率 | K11: 季度≥50% | L11: 2、不达标 汰换：季度 目标达成率<50% | M11: / | N11: / | O11: ✅ | P11: ✅ | Q11: / | R11: 2026/1/1 （26年Q1执行）
B12: ✅ | C12: ✅ | D12: ✅ | E12: ✅ | F12: ✅ | G12: ✅ | L12: 3、末位淘汰 汰换：季度 目标达成率排名为大区内排名最后一名且<100% （假如此季度大区内已有省区总监汰换那就不生效） | M12: / | N12: / | O12: ✅ | P12: ✅ | Q12: / | R12: 2026/1/1 （26年Q1执行）
I13: 双季度考核 （完整季度在岗） | J13: 连续两个季度目标达成率 | K13: 连续两个季度≥75% | L13: 4、不达标 汰换：连续两个季度 目标达成率<75% | M13: / | N13: / | O13: ✅ | P13: ✅ | Q13: / | R13: 2026/1/1 （26年Q2执行）
B15: ✅ | C15: / | D15: ✅ | E15: ✅ | F15: ✅ | G15: ✅ | H15: 区域总监 | I15: 月度考核 （完整月度在岗） | J15: 月度目标达成率 | K15: 月度≥50% | L15: 1、不达标 汰换：月度 目标达成率<50% | M15: / | N15: ✅ | O15: ✅ | P15: / | Q15: / | R15: 45748
I16: 单季度考核 （完整季度在岗） | J16: 季度目标达成率 | K16: 季度≥50% | L16: 2、不达标 汰换：季度 目标达成率<50% | M16: / | N16: ✅ | O16: ✅ | P16: ✅ | Q16: / | R16: 45748
B17: ✅ | C17: ✅ | D17: ✅ | E17: ✅ | F17: ✅ | G17: ✅ | L17: 3、末位淘汰 汰换：季度 目标达成率排名为大区内排名最后一名且<100% （假如此季度大区内已有区域总监汰换那就不生效） | M17: / | N17: ✅ | O17: ✅ | P17: ✅ | Q17: / | R17: 2026/1/1 （26年Q1执行）
I18: 双季度考核 （完整季度在岗） | J18: 连续两个季度目标达成率 | K18: 连续两个季度≥75% | L18: 4、不达标 汰换：连续两个季度 目标达成率<75% | M18: / | N18: ✅ | O18: ✅ | P18: ✅ | Q18: / | R18: 2026/1/1 （26年Q2执行）
B20: ✅ | C20: / | D20: ✅ | E20: ✅ | F20: ✅ | G20: ✅ | H20: 区域经理 | I20: 月度考核 （完整月度在岗） | J20: 月度目标达成率 | K20: 月度≥50% | L20: 1、不达标 汰换：月度 目标达成率<50% | M20: ✅ | N20: ✅ | O20: ✅ | P20: / | Q20: / | R20: 45748
I21: 单季度考核 （完整季度在岗） | J21: 季度目标达成率 | K21: 季度≥50% | L21: 2、不达标 汰换：季度 目标达成率<50% | M21: ✅ | N21: ✅ | O21: ✅ | P21: / | Q21: / | R21: 45748
B22: ✅ | C22: ✅ | D22: ✅ | E22: ✅ | F22: ✅ | G22: ✅ | L22: 3、不达标 汰换：连续两个季度 目标达成率<50% | M22: ✅ | N22: ✅ | O22: ✅ | P22: ✅ | Q22: / | R22: 2026/3/1 （26年Q2执行）
I23: 双季度考核 （完整季度在岗） | J23: 连续两个季度目标达成率 | K23: 连续两个季度≥75% | L23: 4、不达标 汰换：连续两个季度 目标达成率<75% | M23: ✅ | N23: ✅ | O23: ✅ | P23: / | Q23: / | R23: 2026/1/1 （26年Q2执行）
B25: ✅ | C25: ✅ | D25: ✅ | E25: ✅ | F25: ✅ | G25: ✅ | H25: 省区总监 | I25: 各组别内 大区总监空岗，各考核岗位 月度考核、单季度考核、双季度考核 不达标 汰换 | M25: / | N25: / | O25: / | P25: / | Q25: ✅ | R25: 2026/2/1 （26年2月执行）
H26: 区域总监 | M26: / | N26: ✅ | O26: / | P26: / | Q26: ✅
H27: 区域经理 | M27: ✅ | N27: ✅ | O27: / | P27: / | Q27: ✅

Sheet 无上级营业所最低目标
A2: 产品组 | B2: 大区 | C2: 省区名称 | D2: 分公司名称 | E2: 营业所名称 | F2: 无上级 营业所最低目标设置
F3: 儿童乳品组 | G3: 旺旺乳品组 | H3: 标箱组 | I3: 糖果组
A4: 儿童乳品组 | B4: 东北区 | C4: 黑龙江省 | D4: 哈尔滨分 | E4: 大庆所 | F4: 150000 | G4: 150000 | H4: 112500 | I4: 75000
A5: 儿童乳品组 | B5: 东北区 | C5: 黑龙江省 | D5: 哈尔滨分 | E5: 哈尔滨东所 | F5: 180000 | G5: 180000 | H5: 135000 | I5: 90000
A6: 儿童乳品组 | B6: 东北区 | C6: 黑龙江省 | D6: 哈尔滨分 | E6: 哈尔滨西所 | F6: 180000 | G6: 180000 | H6: 135000 | I6: 90000
A7: 儿童乳品组 | B7: 东北区 | C7: 黑龙江省 | D7: 哈尔滨分 | E7: 黑河所 | F7: 120000 | G7: 120000 | H7: 90000 | I7: 60000
A8: 儿童乳品组 | B8: 东北区 | C8: 黑龙江省 | D8: 哈尔滨分 | E8: 呼伦贝尔所 | F8: 120000 | G8: 120000 | H8: 90000 | I8: 60000
A9: 儿童乳品组 | B9: 东北区 | C9: 黑龙江省 | D9: 哈尔滨分 | E9: 鸡西所 | F9: 120000 | G9: 120000 | H9: 90000 | I9: 60000
A10: 儿童乳品组 | B10: 东北区 | C10: 黑龙江省 | D10: 哈尔滨分 | E10: 佳木斯所 | F10: 150000 | G10: 150000 | H10: 112500 | I10: 75000
A11: 儿童乳品组 | B11: 东北区 | C11: 黑龙江省 | D11: 哈尔滨分 | E11: 牡丹江所 | F11: 120000 | G11: 120000 | H11: 90000 | I11: 60000
A12: 儿童乳品组 | B12: 东北区 | C12: 黑龙江省 | D12: 哈尔滨分 | E12: 齐齐哈尔所 | F12: 180000 | G12: 180000 | H12: 135000 | I12: 90000
A13: 儿童乳品组 | B13: 东北区 | C13: 黑龙江省 | D13: 哈尔滨分 | E13: 双鸭山所 | F13: 120000 | G13: 120000 | H13: 90000 | I13: 60000
A14: 儿童乳品组 | B14: 东北区 | C14: 黑龙江省 | D14: 哈尔滨分 | E14: 绥化所 | F14: 150000 | G14: 150000 | H14: 112500 | I14: 75000
A15: 儿童乳品组 | B15: 东北区 | C15: 吉林省 | D15: 长春分 | E15: 白城所 | F15: 120000 | G15: 120000 | H15: 90000 | I15: 60000
... A418: 儿童乳品组 | B418: 西南区 | C418: 重庆市 | D418: 重庆分 | E418: 云阳所 | F418: 150000 | G418: 150000 | H418: 112500 | I418: 75000

Sheet Sheet1
D2: 用人口数设置管控目标
B3: 大区 | C3: 省区数 | D3: 现有目标低于管控目标个数 | E3: 占比 | F3: 分公司数 | G3: 现有目标低于管控目标个数 | H3: 占比
B4: 滨海区 | C4: =COUNTIFS(#REF!,Sheet1!B4,#REF!,"省区总监") -> #REF! | D4: =COUNTIFS(#REF!,Sheet1!B4,#REF!,"省区总监",#REF!,"<0") -> #REF! | E4: =D4/C4 -> #REF! | F4: =COUNTIFS(#REF!,Sheet1!B4,#REF!,"区域总监") -> #REF! | G4: =COUNTIFS(#REF!,Sheet1!B4,#REF!,"区域总监",#REF!,"<0") -> #REF! | H4: =G4/F4 -> #REF!
B5: 华北区 | C5: =COUNTIFS(#REF!,Sheet1!B5,#REF!,"省区总监") -> #REF! | D5: =COUNTIFS(#REF!,Sheet1!B5,#REF!,"省区总监",#REF!,"<0") -> #REF! | E5: =D5/C5 -> #REF! | F5: =COUNTIFS(#REF!,Sheet1!B5,#REF!,"区域总监") -> #REF! | G5: =COUNTIFS(#REF!,Sheet1!B5,#REF!,"区域总监",#REF!,"<0") -> #REF! | H5: =G5/F5 -> #REF!
B6: 华东区 | C6: =COUNTIFS(#REF!,Sheet1!B6,#REF!,"省区总监") -> #REF! | D6: =COUNTIFS(#REF!,Sheet1!B6,#REF!,"省区总监",#REF!,"<0") -> #REF! | E6: =D6/C6 -> #REF! | F6: =COUNTIFS(#REF!,Sheet1!B6,#REF!,"区域总监") -> #REF! | G6: =COUNTIFS(#REF!,Sheet1!B6,#REF!,"区域总监",#REF!,"<0") -> #REF! | H6: =G6/F6 -> #REF!
B7: 华南区 | C7: =COUNTIFS(#REF!,Sheet1!B7,#REF!,"省区总监") -> #REF! | D7: =COUNTIFS(#REF!,Sheet1!B7,#REF!,"省区总监",#REF!,"<0") -> #REF! | E7: =D7/C7 -> #REF! | F7: =COUNTIFS(#REF!,Sheet1!B7,#REF!,"区域总监") -> #REF! | G7: =COUNTIFS(#REF!,Sheet1!B7,#REF!,"区域总监",#REF!,"<0") -> #REF! | H7: =G7/F7 -> #REF!
B8: 华中区 | C8: =COUNTIFS(#REF!,Sheet1!B8,#REF!,"省区总监") -> #REF! | D8: =COUNTIFS(#REF!,Sheet1!B8,#REF!,"省区总监",#REF!,"<0") -> #REF! | E8: =D8/C8 -> #REF! | F8: =COUNTIFS(#REF!,Sheet1!B8,#REF!,"区域总监") -> #REF! | G8: =COUNTIFS(#REF!,Sheet1!B8,#REF!,"区域总监",#REF!,"<0") -> #REF! | H8: =G8/F8 -> #REF!
B9: 西南区 | C9: =COUNTIFS(#REF!,Sheet1!B9,#REF!,"省区总监") -> #REF! | D9: =COUNTIFS(#REF!,Sheet1!B9,#REF!,"省区总监",#REF!,"<0") -> #REF! | E9: =D9/C9 -> #REF! | F9: =COUNTIFS(#REF!,Sheet1!B9,#REF!,"区域总监") -> #REF! | G9: =COUNTIFS(#REF!,Sheet1!B9,#REF!,"区域总监",#REF!,"<0") -> #REF! | H9: =G9/F9 -> #REF!
B10: 合计 | C10: =SUM(C4:C9) -> #REF! | D10: =SUM(D4:D9) -> #REF! | E10: =D10/C10 -> #REF! | F10: =SUM(F4:F9) -> #REF! | G10: =SUM(G4:G9) -> #REF! | H10: =G10/F10 -> #REF!

Sheet 目标测算汇总
G1: 全国占比
B2: 产品组 | C2: 大区 | D2: 省区 | E2: 营业所 | F2: 人口数 （万人） | G2: 人口数 占比 | H2: 是否 启动 | I2: 负责人 | J2: 岗位 | K2: 26-Q2季度目标 （按组织+人拆分） | L2: 管控目标 | M2: 管控目 标增长率
B3: 标箱组 | C3: 华东区 | D3: 华东区 | E3: 华东区 | F3: =SUMIF($C$12:$C$42,E3,$F$12:$F$42) -> 38504.39 | G3: =F3/F$9 -> 0.27148034 | H3: 是 | I3: 空岗 | J3: 大区总监 | K3: 4920000 | L3: =K3 -> 4920000 | M3: =L3/K3-1 -> 0
B4: 标箱组 | C4: 华南区 | D4: 华南区 | E4: 华南区 | F4: =SUMIF($C$12:$C$42,E4,$F$12:$F$42) -> 23062.47 | G4: =F4/F$9 -> 0.16260502 | H4: 是 | I4: 空岗 | J4: 大区总监 | K4: 1520000 | L4: =K4 -> 1520000 | M4: =L4/K4-1 -> 0
B5: 标箱组 | C5: 华中区 | D5: 华中区 | E5: 华中区 | F5: =SUMIF($C$12:$C$42,E5,$F$12:$F$42) -> 22550.31 | G5: =F5/F$9 -> 0.15899397 | H5: 是 | I5: 空岗 | J5: 大区总监 | K5: 3710000 | L5: =K5 -> 3710000 | M5: =L5/K5-1 -> 0
B6: 标箱组 | C6: 东北区 | D6: 东北区 | E6: 东北区 | F6: =SUMIF($C$12:$C$42,E6,$F$12:$F$42) -> 10918.08 | G6: =F6/F$9 -> 0.076979379 | H6: 是 | I6: 空岗 | J6: 大区总监 | K6: 1400000 | L6: =K6 -> 1400000 | M6: =L6/K6-1 -> 0
B7: 标箱组 | C7: 华北区 | D7: 华北区 | E7: 华北区 | F7: =SUMIF($C$12:$C$42,E7,$F$12:$F$42) -> 16404.77 | G7: =F7/F$9 -> 0.11566402 | H7: 是 | I7: 空岗 | J7: 大区总监 | K7: 1960000 | L7: =K7 -> 1960000 | M7: =L7/K7-1 -> 0
B8: 标箱组 | C8: 西南区 | D8: 西南区 | E8: 西南区 | F8: =SUMIF($C$12:$C$42,E8,$F$12:$F$42) -> 30391.21 | G8: =F8/F$9 -> 0.21427728 | H8: 是 | I8: 空岗 | J8: 大区总监 | K8: 3400000 | L8: =K8 -> 3400000 | M8: =L8/K8-1 -> 0
B9: 标箱组 | C9: 全国 | D9: 全国 | E9: 全国 | F9: =SUM(F3:F8) -> 141831.23 | G9: =F9/F$9 -> 1 | I9: 张霞麦 | J9: 总督导 | K9: =SUM(K3:K8) -> 16910000 | L9: =SUM(L3:L8) -> 16910000 | M9: =L9/K9-1 -> 0
G10: 大区占比 | M10: 1、增长率<-50%标绿 2、增长率>50%标红
B11: 产品组 | C11: 大区 | D11: 省区 | E11: 营业所 | F11: 人口数 （万人） | G11: 人口数 占比 | H11: 是否 启动 | I11: 负责人 | J11: 岗位 | K11: 26-Q2季度目标 （按组织+人拆分） | L11: 管控目标 （按人口占比） | M11: 管控目 标增长率 | N11: 管控目标 （按上期业绩） | O11: 管控目 标增长率 | Q11: 大区 | R11: 省总人数 | S11: 目标增长 <50% | T11: 增长占比 | U11: 目标增长 50%x<80% | V11: 增长占比 | W11: 目标增长 >80% | X11: 增长占比
B12: 标箱组 | C12: 华东区 | D12: 上海市 | E12: 上海市 | F12: 2475.9 | G12: =F12/(VLOOKUP($C12,$C$3:$F$9,4,0)) -> 0.064301759 | H12: 否 | I12: 空岗 | J12: 省区总监 | L12: =ROUND(VLOOKUP(C12,$C$3:$K$8,9,0)*G12,0) -> 316365 | M12: =IFERROR(L12/K12-1,"") | N12: 1491.9 | O12: =IFERROR(N12/K12-1,0) -> 0 | Q12: 华东区 | R12: 2 | S12: 0 | T12: =S12/R$18 -> 0 | U12: 0 | V12: =U12/R$18 -> 0 | W12: 2 | X12: =W12/R$18 -> 0.18181818
B13: 标箱组 | C13: 华东区 | D13: 安徽省 | E13: 安徽省 | F13: 6146.54 | G13: =F13/(VLOOKUP($C13,$C$3:$F$9,4,0)) -> 0.15963219 | H13: 是 | I13: 李杨帆 | J13: 省区总监 | K13: 700000 | L13: =ROUND(VLOOKUP(C13,$C$3:$K$8,9,0)*G13,0) -> 785390 | M13: =IFERROR(L13/K13-1,"") -> 0.12198571 | N13: 198647.89 | O13: =IFERROR(N13/K13-1,0) -> -0.7162173 | Q13: 华南区 | R13: 0 | S13: 0 | T13: =S13/R$18 -> 0 | U13: 0 | V13: =U13/R$18 -> 0 | W13: 0 | X13: =W13/R$18 -> 0
B14: 标箱组 | C14: 华东区 | D14: 江苏省 | E14: 江苏省 | F14: 8565.08 | G14: =F14/(VLOOKUP($C14,$C$3:$F$9,4,0)) -> 0.22244425 | H14: 是 | I14: 空岗 | J14: 省区总监 | K14: 800000 | L14: =ROUND(VLOOKUP(C14,$C$3:$K$8,9,0)*G14,0) -> 1094426 | M14: =IFERROR(L14/K14-1,"") -> 0.3680325 | N14: 61856.22 | O14: =IFERROR(N14/K14-1,0) -> -0.92267972 | Q14: 华中区 | R14: 2 | S14: 2 | T14: =S14/R$18 -> 0.18181818 | U14: 0 | V14: =U14/R$18 -> 0 | W14: 0 | X14: =W14/R$18 -> 0
B15: 标箱组 | C15: 华东区 | D15: 浙江省 | E15: 浙江省 | F15: 6623.7 | G15: =F15/(VLOOKUP($C15,$C$3:$F$9,4,0)) -> 0.17202454 | H15: 是 | I15: 空岗 | J15: 省区总监 | K15: 1840000 | L15: =ROUND(VLOOKUP(C15,$C$3:$K$8,9,0)*G15,0) -> 846361 | M15: =IFERROR(L15/K15-1,"") -> -0.5400212 | N15: 129053.7 | O15: =IFERROR(N15/K15-1,0) -> -0.92986212 | Q15: 东北区 | R15: 2 | S15: 2 | T15: =S15/R$18 -> 0.18181818 | U15: 0 | V15: =U15/R$18 -> 0 | W15: 0 | X15: =W15/R$18 -> 0
B16: 标箱组 | C16: 华东区 | D16: 江西省 | E16: 江西省 | F16: 4527.52 | G16: =F16/(VLOOKUP($C16,$C$3:$F$9,4,0)) -> 0.11758451 | H16: 是 | I16: 空岗 | J16: 省区总监 | K16: 580000 | L16: =ROUND(VLOOKUP(C16,$C$3:$K$8,9,0)*G16,0) -> 578516 | M16: =IFERROR(L16/K16-1,"") -> -0.0025586207 | N16: 0 | O16: =IFERROR(N16/K16-1,0) -> -1 | Q16: 华北区 | R16: 3 | S16: 3 | T16: =S16/R$18 -> 0.27272727 | U16: 0 | V16: =U16/R$18 -> 0 | W16: 0 | X16: =W16/R$18 -> 0
B17: 标箱组 | C17: 华东区 | D17: 山东省 | E17: 山东省 | F17: 10165.65 | G17: =F17/(VLOOKUP($C17,$C$3:$F$9,4,0)) -> 0.26401275 | H17: 是 | I17: 李宏权 | J17: 省区总监 | K17: 1000000 | L17: =ROUND(VLOOKUP(C17,$C$3:$K$8,9,0)*G17,0) -> 1298943 | M17: =IFERROR(L17/K17-1,"") -> 0.298943 | N17: 384130.04 | O17: =IFERROR(N17/K17-1,0) -> -0.61586996 | Q17: 西南区 | R17: 2 | S17: 0 | T17: =S17/R$18 -> 0 | U17: 0 | V17: =U17/R$18 -> 0 | W17: 2 | X17: =W17/R$18 -> 0.18181818
B18: 标箱组 | C18: 华南区 | D18: 广东省 | E18: 广东省 | F18: 12714.78 | G18: =F18/(VLOOKUP($C18,$C$3:$F$9,4,0)) -> 0.55131909 | H18: 否 | I18: 空岗 | J18: 省区总监 | L18: =ROUND(VLOOKUP(C18,$C$3:$K$8,9,0)*G18,0) -> 838005 | M18: =IFERROR(L18/K18-1,"") | N18: 40687.25 | O18: =IFERROR(N18/K18-1,0) -> 0 | Q18: 全国 | R18: =SUM(R12:R17) -> 11 | S18: =SUM(S12:S17) -> 7 | T18: =S18/R$18 -> 0.63636364 | U18: =SUM(U12:U17) -> 0 | V18: =U18/R$18 -> 0 | W18: =SUM(W12:W17) -> 4 | X18: =W18/R$18 -> 0.36363636
B19: 标箱组 | C19: 华南区 | D19: 海南省 | E19: 海南省 | F19: 1038.23 | G19: =F19/(VLOOKUP($C19,$C$3:$F$9,4,0)) -> 0.045018162 | H19: 否 | I19: 空岗 | J19: 省区总监 | L19: =ROUND(VLOOKUP(C19,$C$3:$K$8,9,0)*G19,0) -> 68428 | M19: =IFERROR(L19/K19-1,"") | N19: 0 | O19: =IFERROR(N19/K19-1,0) -> 0
B20: 标箱组 | C20: 华南区 | D20: 广西壮族自治区 | E20: 广西壮族自治区 | F20: 5128.51 | G20: =F20/(VLOOKUP($C20,$C$3:$F$9,4,0)) -> 0.22237471 | H20: 是 | I20: 空岗 | J20: 省区总监 | K20: 900000 | L20: =ROUND(VLOOKUP(C20,$C$3:$K$8,9,0)*G20,0) -> 338010 | M20: =IFERROR(L20/K20-1,"") -> -0.62443333 | N20: 50823.5 | O20: =IFERROR(N20/K20-1,0) -> -0.94352944
B21: 标箱组 | C21: 华南区 | D21: 福建省 | E21: 福建省 | F21: 4180.95 | G21: =F21/(VLOOKUP($C21,$C$3:$F$9,4,0)) -> 0.18128804 | H21: 是 | I21: 空岗 | J21: 省区总监 | K21: 620000 | L21: =ROUND(VLOOKUP(C21,$C$3:$K$8,9,0)*G21,0) -> 275558 | M21: =IFERROR(L21/K21-1,"") -> -0.55555161 | N21: 3773.5 | O21: =IFERROR(N21/K21-1,0) -> -0.99391371
B22: 标箱组 | C22: 华中区 | D22: 湖南省 | E22: 湖南省 | F22: 6647.38 | G22: =F22/(VLOOKUP($C22,$C$3:$F$9,4,0)) -> 0.29477998 | H22: 是 | I22: 向林 | J22: 省区总监 | K22: 750000 | L22: =ROUND(VLOOKUP(C22,$C$3:$K$8,9,0)*G22,0) -> 1093634 | M22: =IFERROR(L22/K22-1,"") -> 0.45817867 | N22: 38636.18 | O22: =IFERROR(N22/K22-1,0) -> -0.94848509
B23: 标箱组 | C23: 华中区 | D23: 湖北省 | E23: 湖北省 | F23: 6028.86 | G23: =F23/(VLOOKUP($C23,$C$3:$F$9,4,0)) -> 0.26735154 | H23: 是 | I23: 空岗 | J23: 省区总监 | K23: 360000 | L23: =ROUND(VLOOKUP(C23,$C$3:$K$8,9,0)*G23,0) -> 991874 | M23: =IFERROR(L23/K23-1,"") -> 1.7552056 | N23: 6552.3 | O23: =IFERROR(N23/K23-1,0) -> -0.98179917
B24: 标箱组 | C24: 华中区 | D24: 河南省 | E24: 河南省 | F24: 9874.07 | G24: =F24/(VLOOKUP($C24,$C$3:$F$9,4,0)) -> 0.43786848 | H24: 是 | I24: 朱大伟 | J24: 省区总监 | K24: 2600000 | L24: =ROUND(VLOOKUP(C24,$C$3:$K$8,9,0)*G24,0) -> 1624492 | M24: =IFERROR(L24/K24-1,"") -> -0.37519538 | N24: 1557187.7 | O24: =IFERROR(N24/K24-1,0) -> -0.40108167
B25: 标箱组 | C25: 东北区 | D25: 吉林省 | E25: 吉林省 | F25: 2510.41 | G25: =F25/(VLOOKUP($C25,$C$3:$F$9,4,0)) -> 0.22993145 | H25: 是 | I25: 空岗 | J25: 省区总监 | K25: 100000 | L25: =ROUND(VLOOKUP(C25,$C$3:$K$8,9,0)*G25,0) -> 321904 | M25: =IFERROR(L25/K25-1,"") -> 2.21904 | N25: 58334.32 | O25: =IFERROR(N25/K25-1,0) -> -0.4166568
B26: 标箱组 | C26: 东北区 | D26: 黑龙江省 | E26: 黑龙江省 | F26: 3482.89 | G26: =F26/(VLOOKUP($C26,$C$3:$F$9,4,0)) -> 0.31900206 | H26: 是 | I26: 曾祥海 | J26: 省区总监 | K26: 600000 | L26: =ROUND(VLOOKUP(C26,$C$3:$K$8,9,0)*G26,0) -> 446603 | M26: =IFERROR(L26/K26-1,"") -> -0.25566167 | N26: 152465.35 | O26: =IFERROR(N26/K26-1,0) -> -0.74589108
B27: 标箱组 | C27: 东北区 | D27: 辽宁省 | E27: 辽宁省 | F27: 4924.78 | G27: =F27/(VLOOKUP($C27,$C$3:$F$9,4,0)) -> 0.45106649 | H27: 是 | I27: 李春颜 | J27: 省区总监 | K27: 700000 | L27: =ROUND(VLOOKUP(C27,$C$3:$K$8,9,0)*G27,0) -> 631493 | M27: =IFERROR(L27/K27-1,"") -> -0.097867143 | N27: 273346.65 | O27: =IFERROR(N27/K27-1,0) -> -0.60950479
B28: 标箱组 | C28: 华北区 | D28: 北京市 | E28: 北京市 | F28: 2927.35 | G28: =F28/(VLOOKUP($C28,$C$3:$F$9,4,0)) -> 0.17844505 | H28: 是 | I28: 空岗 | J28: 省区总监 | K28: 110000 | L28: =ROUND(VLOOKUP(C28,$C$3:$K$8,9,0)*G28,0) -> 349752 | M28: =IFERROR(L28/K28-1,"") -> 2.1795636 | N28: 74808.23 | O28: =IFERROR(N28/K28-1,0) -> -0.31992518
B29: 标箱组 | C29: 华北区 | D29: 天津市 | E29: 天津市 | F29: 2990.82 | G29: =F29/(VLOOKUP($C29,$C$3:$F$9,4,0)) -> 0.18231405 | H29: 是 | I29: 张德森 | J29: 省区总监 | K29: 600000 | L29: =ROUND(VLOOKUP(C29,$C$3:$K$8,9,0)*G29,0) -> 357336 | M29: =IFERROR(L29/K29-1,"") -> -0.40444 | N29: 172439.98 | O29: =IFERROR(N29/K29-1,0) -> -0.71260003
B30: 标箱组 | C30: 华北区 | D30: 河北省 | E30: 河北省 | F30: 5035.04 | G30: =F30/(VLOOKUP($C30,$C$3:$F$9,4,0)) -> 0.30692536 | H30: 是 | I30: 尚保刚 | J30: 省区总监 | K30: 800000 | L30: =ROUND(VLOOKUP(C30,$C$3:$K$8,9,0)*G30,0) -> 601574 | M30: =IFERROR(L30/K30-1,"") -> -0.2480325 | N30: 224725.52 | O30: =IFERROR(N30/K30-1,0) -> -0.7190931
B31: 标箱组 | C31: 华北区 | D31: 山西省 | E31: 山西省 | F31: 3481.24 | G31: =F31/(VLOOKUP($C31,$C$3:$F$9,4,0)) -> 0.21220901 | H31: 是 | I31: 王勇 | J31: 省区总监 | K31: 450000 | L31: =ROUND(VLOOKUP(C31,$C$3:$K$8,9,0)*G31,0) -> 415930 | M31: =IFERROR(L31/K31-1,"") -> -0.075711111 | N31: 59954.45 | O31: =IFERROR(N31/K31-1,0) -> -0.86676789
B32: 标箱组 | C32: 华北区 | D32: 内蒙古自治区 | E32: 内蒙古自治区 | F32: 1970.32 | G32: =F32/(VLOOKUP($C32,$C$3:$F$9,4,0)) -> 0.12010653 | H32: 否 | I32: 空岗 | J32: 省区总监 | L32: =ROUND(VLOOKUP(C32,$C$3:$K$8,9,0)*G32,0) -> 235409 | M32: =IFERROR(L32/K32-1,"") | N32: 32182.02 | O32: =IFERROR(N32/K32-1,0) -> 0
B33: 标箱组 | C33: 西南区 | D33: 重庆市 | E33: 重庆市 | F33: 3728.39 | G33: =F33/(VLOOKUP($C33,$C$3:$F$9,4,0)) -> 0.12267988 | H33: 是 | I33: 马凡平 | J33: 省区总监 | K33: 800000 | L33: =ROUND(VLOOKUP(C33,$C$3:$K$8,9,0)*G33,0) -> 417112 | M33: =IFERROR(L33/K33-1,"") -> -0.47861 | N33: 247384.35 | O33: =IFERROR(N33/K33-1,0) -> -0.69076956
B34: 标箱组 | C34: 西南区 | D34: 四川省 | E34: 四川省 | F34: 7848.26 | G34: =F34/(VLOOKUP($C34,$C$3:$F$9,4,0)) -> 0.25824112 | H34: 是 | I34: 瞿慧 | J34: 省区总监 | K34: 800000 | L34: =ROUND(VLOOKUP(C34,$C$3:$K$8,9,0)*G34,0) -> 878020 | M34: =IFERROR(L34/K34-1,"") -> 0.097525 | N34: 390980.85 | O34: =IFERROR(N34/K34-1,0) -> -0.51127394
B35: 标箱组 | C35: 西南区 | D35: 云南省 | E35: 云南省 | F35: 4724.33 | G35: =F35/(VLOOKUP($C35,$C$3:$F$9,4,0)) -> 0.15545054 | H35: 是 | I35: 空岗 | J35: 省区总监 | K35: 250000 | L35: =ROUND(VLOOKUP(C35,$C$3:$K$8,9,0)*G35,0) -> 528532 | M35: =IFERROR(L35/K35-1,"") -> 1.114128 | N35: 94021.44 | O35: =IFERROR(N35/K35-1,0) -> -0.62391424
B36: 标箱组 | C36: 西南区 | D36: 贵州省 | E36: 贵州省 | F36: 3859.22 | G36: =F36/(VLOOKUP($C36,$C$3:$F$9,4,0)) -> 0.12698474 | H36: 是 | I36: 空岗 | J36: 省区总监 | K36: 950000 | L36: =ROUND(VLOOKUP(C36,$C$3:$K$8,9,0)*G36,0) -> 431748 | M36: =IFERROR(L36/K36-1,"") -> -0.54552842 | N36: 14956.49 | O36: =IFERROR(N36/K36-1,0) -> -0.98425633
B37: 标箱组 | C37: 西南区 | D37: 陕西省 | E37: 陕西省 | F37: 4562.98 | G37: =F37/(VLOOKUP($C37,$C$3:$F$9,4,0)) -> 0.15014144 | H37: 是 | I37: 空岗 | J37: 省区总监 | K37: 350000 | L37: =ROUND(VLOOKUP(C37,$C$3:$K$8,9,0)*G37,0) -> 510481 | M37: =IFERROR(L37/K37-1,"") -> 0.45851714 | N37: 22107.42 | O37: =IFERROR(N37/K37-1,0) -> -0.93683594
B38: 标箱组 | C38: 西南区 | D38: 甘肃省 | E38: 甘肃省 | F38: 3391.46 | G38: =F38/(VLOOKUP($C38,$C$3:$F$9,4,0)) -> 0.11159345 | H38: 是 | I38: 空岗 | J38: 省区总监 | K38: 250000 | L38: =ROUND(VLOOKUP(C38,$C$3:$K$8,9,0)*G38,0) -> 379418 | M38: =IFERROR(L38/K38-1,"") -> 0.517672 | N38: 29922.75 | O38: =IFERROR(N38/K38-1,0) -> -0.880309
B39: 标箱组 | C39: 西南区 | D39: 西藏自治区 | E39: 西藏自治区 | F39: 0 | G39: =F39/(VLOOKUP($C39,$C$3:$F$9,4,0)) -> 0 | H39: 否 | I39: 空岗 | J39: 省区总监 | L39: =ROUND(VLOOKUP(C39,$C$3:$K$8,9,0)*G39,0) -> 0 | M39: =IFERROR(L39/K39-1,"") | N39: 0 | O39: =IFERROR(N39/K39-1,0) -> 0
B40: 标箱组 | C40: 西南区 | D40: 宁夏回族自治区 | E40: 宁夏回族自治区 | F40: 0 | G40: =F40/(VLOOKUP($C40,$C$3:$F$9,4,0)) -> 0 | H40: 否 | I40: 空岗 | J40: 省区总监 | L40: =ROUND(VLOOKUP(C40,$C$3:$K$8,9,0)*G40,0) -> 0 | M40: =IFERROR(L40/K40-1,"") | N40: 0 | O40: =IFERROR(N40/K40-1,0) -> 0
...

Sheet 营业所测算
C2: 产品组 | D2: 大区 | E2: 省区 | F2: 营业所 | G2: 是否 启动 | H2: 负责人 | I2: 岗位 | J2: 26-Q2季度目标 （按组织+人拆分） | K2: 26-Q2季度目标 （按人拆分）
C3: 标箱组 | D3: 东北区 | E3: 辽宁省 | F3: 大东所 | G3: 是 | H3: 董绍峰 | I3: 区域经理 | J3: 40000 | K3: 112500
C4: 标箱组 | D4: 东北区 | E4: 辽宁省 | F4: 通辽所 | G4: 是 | H4: 卢鑫宇 | I4: 区域经理 | J4: 60000 | K4: 132500
C5: 标箱组 | D5: 东北区 | E5: 辽宁省 | F5: 赤峰所 | G5: 是 | H5: 高洪雁 | I5: 区域经理 | J5: 70000 | K5: 142500
C6: 标箱组 | D6: 东北区 | E6: 辽宁省 | F6: 金州所 | G6: 是 | H6: 邹沛梓 | I6: 区域经理 | J6: 55000 | K6: 127500
C7: 标箱组 | D7: 东北区 | E7: 辽宁省 | F7: 锦州所 | G7: 是 | H7: 孟伟 | I7: 区域经理 | J7: 60000 | K7: 132500
C8: 标箱组 | D8: 东北区 | E8: 辽宁省 | F8: 鞍山所 | G8: 是 | H8: 姜文章 | I8: 区域经理 | J8: 30000 | K8: 102500
C9: 标箱组 | D9: 东北区 | E9: 黑龙江省 | F9: 哈尔滨西所 | G9: 是 | H9: 郭峰 | I9: 区域经理 | J9: 150000 | K9: 650000
C10: 标箱组 | D10: 华中区 | E10: 河南省 | F10: 安阳所 | G10: 是 | H10: 王志宾 | I10: 区域经理 | J10: 90000 | K10: 308889
C11: 标箱组 | D11: 华中区 | E11: 河南省 | F11: 周口所 | G11: 是 | H11: 胡鹏 | I11: 区域经理 | J11: 150000 | K11: 308889
C12: 标箱组 | D12: 华中区 | E12: 河南省 | F12: 商丘所 | G12: 是 | H12: 王夏冰 | I12: 区域经理 | J12: 120000 | K12: 308889
C13: 标箱组 | D13: 华中区 | E13: 河南省 | F13: 尉氏所 | G13: 是 | H13: 胡丹 | I13: 区域经理 | J13: 90000 | K13: 308889
C14: 标箱组 | D14: 华中区 | E14: 河南省 | F14: 洛阳所 | G14: 是 | H14: 张腾飞 | I14: 区域经理 | J14: 180000 | K14: 308889
... C31: 标箱组 | D31: 西南区 | E31: 重庆市 | F31: 黔江所 | G31: 是 | H31: 张豪 | I31: 区域经理 | J31: 75000 | K31: 1700000

Sheet 组别目标-标箱组
C3: 序号 | D3: 产品组 | E3: 大区 | F3: 省区 | G3: 分公司 | H3: 营业所 | I3: 人口数 | J3: 人口占比 | K3: 是否 启动 | L3: 负责人 | M3: 是否兼岗 | N3: 岗位 | O3: 26-Q2季度目标 （按组织+人拆分） | P3: 管控目标 | Q3: 26-Q2季度目标 （按人拆分）
A4: =E4&F4&H4 -> 华东区 | B4: =D4&E4 -> 标箱组华东区 | C4: =MATCH(E4,_xlfn.UNIQUE(E$4:E$9),0) -> 1 | D4: 标箱组 | E4: 华东区 | I4: 38504.39 | J4: =I4/SUMIF($D$41:$D$456,$D4,$I$41:$I$456) -> 0.27148034 | K4: 是 | N4: 大区总监 | O4: 4920000 | P4: =O4 -> 4920000 | Q4: 4920000
A5: =E5&F5&H5 -> 华南区 | B5: =D5&E5 -> 标箱组华南区 | C5: =MATCH(E5,_xlfn.UNIQUE(E$4:E$9),0) -> 2 | D5: 标箱组 | E5: 华南区 | I5: 23062.47 | J5: =I5/SUMIF($D$41:$D$456,$D5,$I$41:$I$456) -> 0.16260502 | K5: 是 | N5: 大区总监 | O5: 1520000 | P5: =O5 -> 1520000 | Q5: 1520000
A6: =E6&F6&H6 -> 华中区 | B6: =D6&E6 -> 标箱组华中区 | C6: =MATCH(E6,_xlfn.UNIQUE(E$4:E$9),0) -> 3 | D6: 标箱组 | E6: 华中区 | I6: 22550.31 | J6: =I6/SUMIF($D$41:$D$456,$D6,$I$41:$I$456) -> 0.15899397 | K6: 是 | N6: 大区总监 | O6: 3710000 | P6: =O6 -> 3710000 | Q6: 3710000
A7: =E7&F7&H7 -> 东北区 | B7: =D7&E7 -> 标箱组东北区 | C7: =MATCH(E7,_xlfn.UNIQUE(E$4:E$9),0) -> 4 | D7: 标箱组 | E7: 东北区 | I7: 10918.08 | J7: =I7/SUMIF($D$41:$D$456,$D7,$I$41:$I$456) -> 0.076979379 | K7: 是 | N7: 大区总监 | O7: 1400000 | P7: =O7 -> 1400000 | Q7: 1400000
A8: =E8&F8&H8 -> 华北区 | B8: =D8&E8 -> 标箱组华北区 | C8: =MATCH(E8,_xlfn.UNIQUE(E$4:E$9),0) -> 5 | D8: 标箱组 | E8: 华北区 | I8: 16404.77 | J8: =I8/SUMIF($D$41:$D$456,$D8,$I$41:$I$456) -> 0.11566402 | K8: 是 | N8: 大区总监 | O8: 1960000 | P8: =O8 -> 1960000 | Q8: 1960000
A9: =E9&F9&H9 -> 西南区 | B9: =D9&E9 -> 标箱组西南区 | C9: =MATCH(E9,_xlfn.UNIQUE(E$4:E$9),0) -> 6 | D9: 标箱组 | E9: 西南区 | I9: 30391.21 | J9: =I9/SUMIF($D$41:$D$456,$D9,$I$41:$I$456) -> 0.21427728 | K9: 是 | N9: 大区总监 | O9: 3400000 | P9: =O9 -> 3400000 | Q9: 3400000
A10: =E10&F10&H10 -> 华东区上海市 | B10: =IF(N10="省区总监",D10&F10,D10&H10) -> 标箱组上海市 | C10: =MATCH(B10,_xlfn.UNIQUE(B$10:B$40),0) -> 1 | D10: 标箱组 | E10: 华东区 | F10: 上海市 | I10: 2475.9 | J10: =I10/SUMIF($E$41:$E$456,$E10,$I$41:$I$456) -> 0.064301759 | K10: 否 | L10: 空岗 | N10: 省区总监 | P10: =ROUND(J10*VLOOKUP(E10,E:P,12,0),0) -> 316365 | Q10: 0
A11: =E11&F11&H11 -> 华东区安徽省 | B11: =IF(N11="省区总监",D11&F11,D11&H11) -> 标箱组安徽省 | C11: =MATCH(B11,_xlfn.UNIQUE(B$10:B$40),0) -> 2 | D11: 标箱组 | E11: 华东区 | F11: 安徽省 | I11: 6146.54 | J11: =I11/SUMIF($E$41:$E$456,$E11,$I$41:$I$456) -> 0.15963219 | K11: 是 | L11: 李杨帆 | M11: 否 | N11: 省区总监 | O11: 700000 | P11: =ROUND(J11*VLOOKUP(E11,E:P,12,0),0) -> 785390 | Q11: 2310000
A12: =E12&F12&H12 -> 华东区江苏省 | B12: =IF(N12="省区总监",D12&F12,D12&H12) -> 标箱组江苏省 | C12: =MATCH(B12,_xlfn.UNIQUE(B$10:B$40),0) -> 3 | D12: 标箱组 | E12: 华东区 | F12: 江苏省 | I12: 8565.08 | J12: =I12/SUMIF($E$41:$E$456,$E12,$I$41:$I$456) -> 0.22244425 | K12: 是 | L12: 空岗 | N12: 省区总监 | O12: 800000 | P12: =ROUND(J12*VLOOKUP(E12,E:P,12,0),0) -> 1094426 | Q12: 0
A13: =E13&F13&H13 -> 华东区浙江省 | B13: =IF(N13="省区总监",D13&F13,D13&H13) -> 标箱组浙江省 | C13: =MATCH(B13,_xlfn.UNIQUE(B$10:B$40),0) -> 4 | D13: 标箱组 | E13: 华东区 | F13: 浙江省 | I13: 6623.7 | J13: =I13/SUMIF($E$41:$E$456,$E13,$I$41:$I$456) -> 0.17202454 | K13: 是 | L13: 空岗 | N13: 省区总监 | O13: 1840000 | P13: =ROUND(J13*VLOOKUP(E13,E:P,12,0),0) -> 846361 | Q13: 0
A14: =E14&F14&H14 -> 华东区江西省 | B14: =IF(N14="省区总监",D14&F14,D14&H14) -> 标箱组江西省 | C14: =MATCH(B14,_xlfn.UNIQUE(B$10:B$40),0) -> 5 | D14: 标箱组 | E14: 华东区 | F14: 江西省 | I14: 4527.52 | J14: =I14/SUMIF($E$41:$E$456,$E14,$I$41:$I$456) -> 0.11758451 | K14: 是 | L14: 空岗 | N14: 省区总监 | O14: 580000 | P14: =ROUND(J14*VLOOKUP(E14,E:P,12,0),0) -> 578516 | Q14: 0
A15: =E15&F15&H15 -> 华东区山东省 | B15: =IF(N15="省区总监",D15&F15,D15&H15) -> 标箱组山东省 | C15: =MATCH(B15,_xlfn.UNIQUE(B$10:B$40),0) -> 6 | D15: 标箱组 | E15: 华东区 | F15: 山东省 | I15: 10165.65 | J15: =I15/SUMIF($E$41:$E$456,$E15,$I$41:$I$456) -> 0.26401275 | K15: 是 | L15: 李宏权 | M15: 否 | N15: 省区总监 | O15: 1000000 | P15: =ROUND(J15*VLOOKUP(E15,E:P,12,0),0) -> 1298943 | Q15: 2610000
A16: =E16&F16&H16 -> 华南区广东省 | B16: =IF(N16="省区总监",D16&F16,D16&H16) -> 标箱组广东省 | C16: =MATCH(B16,_xlfn.UNIQUE(B$10:B$40),0) -> 7 | D16: 标箱组 | E16: 华南区 | F16: 广东省 | I16: 12714.78 | J16: =I16/SUMIF($E$41:$E$456,$E16,$I$41:$I$456) -> 0.55131909 | K16: 否 | L16: 空岗 | N16: 省区总监 | O16: 0 | P16: =ROUND(J16*VLOOKUP(E16,E:P,12,0),0) -> 838005 | Q16: 0
A17: =E17&F17&H17 -> 华南区海南省 | B17: =IF(N17="省区总监",D17&F17,D17&H17) -> 标箱组海南省 | C17: =MATCH(B17,_xlfn.UNIQUE(B$10:B$40),0) -> 8 | D17: 标箱组 | E17: 华南区 | F17: 海南省 | I17: 1038.23 | J17: =I17/SUMIF($E$41:$E$456,$E17,$I$41:$I$456) -> 0.045018162 | K17: 否 | L17: 空岗 | N17: 省区总监 | O17: 0 | P17: =ROUND(J17*VLOOKUP(E17,E:P,12,0),0) -> 68428 | Q17: 0
A18: =E18&F18&H18 -> 华南区广西壮族自治区 | B18: =IF(N18="省区总监",D18&F18,D18&H18) -> 标箱组广西壮族自治区 | C18: =MATCH(B18,_xlfn.UNIQUE(B$10:B$40),0) -> 9 | D18: 标箱组 | E18: 华南区 | F18: 广西壮族自治区 | I18: 5128.51 | J18: =I18/SUMIF($E$41:$E$456,$E18,$I$41:$I$456) -> 0.22237471 | K18: 是 | L18: 空岗 | N18: 省区总监 | O18: 900000 | P18: =ROUND(J18*VLOOKUP(E18,E:P,12,0),0) -> 338010 | Q18: 0
A19: =E19&F19&H19 -> 华南区福建省 | B19: =IF(N19="省区总监",D19&F19,D19&H19) -> 标箱组福建省 | C19: =MATCH(B19,_xlfn.UNIQUE(B$10:B$40),0) -> 10 | D19: 标箱组 | E19: 华南区 | F19: 福建省 | I19: 4180.95 | J19: =I19/SUMIF($E$41:$E$456,$E19,$I$41:$I$456) -> 0.18128804 | K19: 是 | L19: 空岗 | N19: 省区总监 | O19: 620000 | P19: =ROUND(J19*VLOOKUP(E19,E:P,12,0),0) -> 275558 | Q19: 0
A20: =E20&F20&H20 -> 华中区湖南省 | B20: =IF(N20="省区总监",D20&F20,D20&H20) -> 标箱组湖南省 | C20: =MATCH(B20,_xlfn.UNIQUE(B$10:B$40),0) -> 11 | D20: 标箱组 | E20: 华中区 | F20: 湖南省 | I20: 6647.38 | J20: =I20/SUMIF($E$41:$E$456,$E20,$I$41:$I$456) -> 0.29477998 | K20: 是 | L20: 向林 | M20: 否 | N20: 省区总监 | O20: 750000 | P20: =ROUND(J20*VLOOKUP(E20,E:P,12,0),0) -> 1093634 | Q20: 930000
A21: =E21&F21&H21 -> 华中区湖北省 | B21: =IF(N21="省区总监",D21&F21,D21&H21) -> 标箱组湖北省 | C21: =MATCH(B21,_xlfn.UNIQUE(B$10:B$40),0) -> 12 | D21: 标箱组 | E21: 华中区 | F21: 湖北省 | I21: 6028.86 | J21: =I21/SUMIF($E$41:$E$456,$E21,$I$41:$I$456) -> 0.26735154 | K21: 是 | L21: 空岗 | N21: 省区总监 | O21: 360000 | P21: =ROUND(J21*VLOOKUP(E21,E:P,12,0),0) -> 991874 | Q21: 0
A22: =E22&F22&H22 -> 华中区河南省 | B22: =IF(N22="省区总监",D22&F22,D22&H22) -> 标箱组河南省 | C22: =MATCH(B22,_xlfn.UNIQUE(B$10:B$40),0) -> 13 | D22: 标箱组 | E22: 华中区 | F22: 河南省 | I22: 9874.07 | J22: =I22/SUMIF($E$41:$E$456,$E22,$I$41:$I$456) -> 0.43786848 | K22: 是 | L22: 朱大伟 | M22: 否 | N22: 省区总监 | O22: 2600000 | P22: =ROUND(J22*VLOOKUP(E22,E:P,12,0),0) -> 1624492 | Q22: 2780000
A23: =E23&F23&H23 -> 东北区辽宁省 | B23: =IF(N23="省区总监",D23&F23,D23&H23) -> 标箱组辽宁省 | C23: =MATCH(B23,_xlfn.UNIQUE(B$10:B$40),0) -> 14 | D23: 标箱组 | E23: 东北区 | F23: 辽宁省 | I23: 4924.78 | J23: =I23/SUMIF($E$41:$E$456,$E23,$I$41:$I$456) -> 0.45106649 | K23: 是 | L23: 李春颜 | M23: 否 | N23: 省区总监 | O23: 700000 | P23: =ROUND(J23*VLOOKUP(E23,E:P,12,0),0) -> 631493 | Q23: 750000
A24: =E24&F24&H24 -> 东北区吉林省 | B24: =IF(N24="省区总监",D24&F24,D24&H24) -> 标箱组吉林省 | C24: =MATCH(B24,_xlfn.UNIQUE(B$10:B$40),0) -> 15 | D24: 标箱组 | E24: 东北区 | F24: 吉林省 | I24: 2510.41 | J24: =I24/SUMIF($E$41:$E$456,$E24,$I$41:$I$456) -> 0.22993145 | K24: 是 | L24: 空岗 | N24: 省区总监 | O24: 100000 | P24: =ROUND(J24*VLOOKUP(E24,E:P,12,0),0) -> 321904 | Q24: 0
A25: =E25&F25&H25 -> 东北区黑龙江省 | B25: =IF(N25="省区总监",D25&F25,D25&H25) -> 标箱组黑龙江省 | C25: =MATCH(B25,_xlfn.UNIQUE(B$10:B$40),0) -> 16 | D25: 标箱组 | E25: 东北区 | F25: 黑龙江省 | I25: 3482.89 | J25: =I25/SUMIF($E$41:$E$456,$E25,$I$41:$I$456) -> 0.31900206 | K25: 是 | L25: 曾祥海 | M25: 否 | N25: 省区总监 | O25: 600000 | P25: =ROUND(J25*VLOOKUP(E25,E:P,12,0),0) -> 446603 | Q25: 650000
A26: =E26&F26&H26 -> 华北区北京市 | B26: =IF(N26="省区总监",D26&F26,D26&H26) -> 标箱组北京市 | C26: =MATCH(B26,_xlfn.UNIQUE(B$10:B$40),0) -> 17 | D26: 标箱组 | E26: 华北区 | F26: 北京市 | I26: 2927.35 | J26: =I26/SUMIF($E$41:$E$456,$E26,$I$41:$I$456) -> 0.17844505 | K26: 是 | L26: 空岗 | N26: 省区总监 | O26: 110000 | P26: =ROUND(J26*VLOOKUP(E26,E:P,12,0),0) -> 349752 | Q26: 0
A27: =E27&F27&H27 -> 华北区天津市 | B27: =IF(N27="省区总监",D27&F27,D27&H27) -> 标箱组天津市 | C27: =MATCH(B27,_xlfn.UNIQUE(B$10:B$40),0) -> 18 | D27: 标箱组 | E27: 华北区 | F27: 天津市 | I27: 2990.82 | J27: =I27/SUMIF($E$41:$E$456,$E27,$I$41:$I$456) -> 0.18231405 | K27: 是 | L27: 张德森 | M27: 否 | N27: 省区总监 | O27: 600000 | P27: =ROUND(J27*VLOOKUP(E27,E:P,12,0),0) -> 357336 | Q27: 636667
A28: =E28&F28&H28 -> 华北区河北省 | B28: =IF(N28="省区总监",D28&F28,D28&H28) -> 标箱组河北省 | C28: =MATCH(B28,_xlfn.UNIQUE(B$10:B$40),0) -> 19 | D28: 标箱组 | E28: 华北区 | F28: 河北省 | I28: 5035.04 | J28: =I28/SUMIF($E$41:$E$456,$E28,$I$41:$I$456) -> 0.30692536 | K28: 是 | L28: 尚保刚 | M28: 否 | N28: 省区总监 | O28: 800000 | P28: =ROUND(J28*VLOOKUP(E28,E:P,12,0),0) -> 601574 | Q28: 836667
A29: =E29&F29&H29 -> 华北区山西省 | B29: =IF(N29="省区总监",D29&F29,D29&H29) -> 标箱组山西省 | C29: =MATCH(B29,_xlfn.UNIQUE(B$10:B$40),0) -> 20 | D29: 标箱组 | E29: 华北区 | F29: 山西省 | I29: 3481.24 | J29: =I29/SUMIF($E$41:$E$456,$E29,$I$41:$I$456) -> 0.21220901 | K29: 是 | L29: 王勇 | M29: 否 | N29: 省区总监 | O29: 450000 | P29: =ROUND(J29*VLOOKUP(E29,E:P,12,0),0) -> 415930 | Q29: 486667
A30: =E30&F30&H30 -> 华北区内蒙古自治区 | B30: =IF(N30="省区总监",D30&F30,D30&H30) -> 标箱组内蒙古自治区 | C30: =MATCH(B30,_xlfn.UNIQUE(B$10:B$40),0) -> 21 | D30: 标箱组 | E30: 华北区 | F30: 内蒙古自治区 | I30: 1970.32 | J30: =I30/SUMIF($E$41:$E$456,$E30,$I$41:$I$456) -> 0.12010653 | K30: 否 | L30: 空岗 | N30: 省区总监 | O30: 0 | P30: =ROUND(J30*VLOOKUP(E30,E:P,12,0),0) -> 235409 | Q30: 0
A31: =E31&F31&H31 -> 西南区重庆市 | B31: =IF(N31="省区总监",D31&F31,D31&H31) -> 标箱组重庆市 | C31: =MATCH(B31,_xlfn.UNIQUE(B$10:B$40),0) -> 22 | D31: 标箱组 | E31: 西南区 | F31: 重庆市 | I31: 3728.39 | J31: =I31/SUMIF($E$41:$E$456,$E31,$I$41:$I$456) -> 0.12267988 | K31: 是 | L31: 马凡平 | M31: 否 | N31: 省区总监 | O31: 800000 | P31: =ROUND(J31*VLOOKUP(E31,E:P,12,0),0) -> 417112 | Q31: 1700000
A32: =E32&F32&H32 -> 西南区四川省 | B32: =IF(N32="省区总监",D32&F32,D32&H32) -> 标箱组四川省 | C32: =MATCH(B32,_xlfn.UNIQUE(B$10:B$40),0) -> 23 | D32: 标箱组 | E32: 西南区 | F32: 四川省 | I32: 7848.26 | J32: =I32/SUMIF($E$41:$E$456,$E32,$I$41:$I$456) -> 0.25824112 | K32: 是 | L32: 瞿慧 | M32: 否 | N32: 省区总监 | O32: 800000 | P32: =ROUND(J32*VLOOKUP(E32,E:P,12,0),0) -> 878020 | Q32: 1700000
A33: =E33&F33&H33 -> 西南区云南省 | B33: =IF(N33="省区总监",D33&F33,D33&H33) -> 标箱组云南省 | C33: =MATCH(B33,_xlfn.UNIQUE(B$10:B$40),0) -> 24 | D33: 标箱组 | E33: 西南区 | F33: 云南省 | I33: 4724.33 | J33: =I33/SUMIF($E$41:$E$456,$E33,$I$41:$I$456) -> 0.15545054 | K33: 是 | L33: 空岗 | N33: 省区总监 | O33: 250000 | P33: =ROUND(J33*VLOOKUP(E33,E:P,12,0),0) -> 528532 | Q33: 0
A34: =E34&F34&H34 -> 西南区贵州省 | B34: =IF(N34="省区总监",D34&F34,D34&H34) -> 标箱组贵州省 | C34: =MATCH(B34,_xlfn.UNIQUE(B$10:B$40),0) -> 25 | D34: 标箱组 | E34: 西南区 | F34: 贵州省 | I34: 3859.22 | J34: =I34/SUMIF($E$41:$E$456,$E34,$I$41:$I$456) -> 0.12698474 | K34: 是 | L34: 空岗 | N34: 省区总监 | O34: 950000 | P34: =ROUND(J34*VLOOKUP(E34,E:P,12,0),0) -> 431748 | Q34: 0
A35: =E35&F35&H35 -> 西南区陕西省 | B35: =IF(N35="省区总监",D35&F35,D35&H35) -> 标箱组陕西省 | C35: =MATCH(B35,_xlfn.UNIQUE(B$10:B$40),0) -> 26 | D35: 标箱组 | E35: 西南区 | F35: 陕西省 | I35: 4562.98 | J35: =I35/SUMIF($E$41:$E$456,$E35,$I$41:$I$456) -> 0.15014144 | K35: 是 | L35: 空岗 | N35: 省区总监 | O35: 350000 | P35: =ROUND(J35*VLOOKUP(E35,E:P,12,0),0) -> 510481 | Q35: 0
A36: =E36&F36&H36 -> 西南区甘肃省 | B36: =IF(N36="省区总监",D36&F36,D36&H36) -> 标箱组甘肃省 | C36: =MATCH(B36,_xlfn.UNIQUE(B$10:B$40),0) -> 27 | D36: 标箱组 | E36: 西南区 | F36: 甘肃省 | I36: 3391.46 | J36: =I36/SUMIF($E$41:$E$456,$E36,$I$41:$I$456) -> 0.11159345 | K36: 是 | L36: 空岗 | N36: 省区总监 | O36: 250000 | P36: =ROUND(J36*VLOOKUP(E36,E:P,12,0),0) -> 379418 | Q36: 0
A37: =E37&F37&H37 -> 西南区西藏自治区 | B37: =IF(N37="省区总监",D37&F37,D37&H37) -> 标箱组西藏自治区 | C37: =MATCH(B37,_xlfn.UNIQUE(B$10:B$40),0) -> 28 | D37: 标箱组 | E37: 西南区 | F37: 西藏自治区 | I37: 0 | J37: =I37/SUMIF($E$41:$E$456,$E37,$I$41:$I$456) -> 0 | K37: 否 | L37: 空岗 | N37: 省区总监 | P37: =ROUND(J37*VLOOKUP(E37,E:P,12,0),0) -> 0 | Q37: 0
A38: =E38&F38&H38 -> 西南区宁夏回族自治区 | B38: =IF(N38="省区总监",D38&F38,D38&H38) -> 标箱组宁夏回族自治区 | C38: =MATCH(B38,_xlfn.UNIQUE(B$10:B$40),0) -> 29 | D38: 标箱组 | E38: 西南区 | F38: 宁夏回族自治区 | I38: 0 | J38: =I38/SUMIF($E$41:$E$456,$E38,$I$41:$I$456) -> 0 | K38: 否 | L38: 空岗 | N38: 省区总监 | P38: =ROUND(J38*VLOOKUP(E38,E:P,12,0),0) -> 0 | Q38: 0
A39: =E39&F39&H39 -> 西南区青海省 | B39: =IF(N39="省区总监",D39&F39,D39&H39) -> 标箱组青海省 | C39: =MATCH(B39,_xlfn.UNIQUE(B$10:B$40),0) -> 30 | D39: 标箱组 | E39: 西南区 | F39: 青海省 | I39: 0 | J39: =I39/SUMIF($E$41:$E$456,$E39,$I$41:$I$456) -> 0 | K39: 否 | L39: 空岗 | N39: 省区总监 | P39: =ROUND(J39*VLOOKUP(E39,E:P,12,0),0) -> 0 | Q39: 0
A40: =E40&F40&H40 -> 西南区新疆维吾尔自治区 | B40: =IF(N40="省区总监",D40&F40,D40&H40) -> 标箱组新疆维吾尔自治区 | C40: =MATCH(B40,_xlfn.UNIQUE(B$10:B$40),0) -> 31 | D40: 标箱组 | E40: 西南区 | F40: 新疆维吾尔自治区 | I40: 2276.57 | J40: =I40/SUMIF($E$41:$E$456,$E40,$I$41:$I$456) -> 0.074908831 | K40: 否 | L40: 空岗 | N40: 省区总监 | P40: =ROUND(J40*VLOOKUP(E40,E:P,12,0),0) -> 254690 | Q40: 0
A41: =E41&F41&H41 -> 东北区吉林省兴安盟所 | B41: =IF(N41="省区总监",D41&F41,D41&H41) -> 标箱组兴安盟所 | C41: 1 | D41: 标箱组 | E41: =_xlfn.XLOOKUP($F41,F:F,E:E) -> 东北区 | F41: 吉林省 | G41: 长春分 | H41: 兴安盟所 | I41: 139.61 | J41: =I41/SUMIF($F$41:$G$456,$F41,$I$41:$I$456) -> 0.05561243 | K41: =_xlfn.XLOOKUP(F41,F:F,K:K,0) -> 是 | L41: 空岗 | N41: 区域经理 | P41: =ROUND(J41*VLOOKUP(F41,F:P,11,0),0) -> 17902 | Q41: 0
A42: =E42&F42&H42 -> 东北区吉林省吉林所 | B42: =IF(N42="省区总监",D42&F42,D42&H42) -> 标箱组吉林所 | C42: 2 | D42: 标箱组 | E42: =_xlfn.XLOOKUP($F42,F:F,E:E) -> 东北区 | F42: 吉林省 | G42: 长春分 | H42: 吉林所 | I42: 362.38 | J42: =I42/SUMIF($F$41:$G$456,$F42,$I$41:$I$456) -> 0.14435092 | K42: =_xlfn.XLOOKUP(F42,F:F,K:K,0) -> 是 | L42: 空岗 | N42: 区域经理 | P42: =ROUND(J42*VLOOKUP(F42,F:P,11,0),0) -> 46467 | Q42: 0
...

Sheet Sheet3
D1: 负责人
D2: 李杨帆 | E2: 业务-1
D3: 李宏权 | E3: 业务-2
D4: 向林 | E4: 业务-3
D5: 朱大伟 | E5: 业务-4
D6: 李春颜 | E6: 业务-5
D7: 曾祥海 | E7: 业务-6
D8: 张德森 | E8: 业务-7
D9: 尚保刚 | E9: 业务-8
D10: 王勇 | E10: 业务-9
D11: 马凡平 | E11: 业务-10
D12: 瞿慧 | E12: 业务-11
D13: 姜文章 | E13: 业务-12
... D42: 张豪 | E42: 业务-41
